<?xml version="1.0" ?>
<!-- =================================================================================== -->
<!-- |    This document was autogenerated by xacro from summit.urdf.xacro              | -->
<!-- |    EDITING THIS FILE BY HAND IS NOT RECOMMENDED                                 | -->
<!-- =================================================================================== -->
<robot name="summit" xmlns:xacro="http://www.ros.org/wiki/xacro">
  <!-- ros_control plugin -->
  <gazebo>
    <plugin filename="libgazebo_ros_control.so" name="ros_control">
      <robotNamespace>/summit</robotNamespace>
      <controlPeriod>0.003</controlPeriod>
      <robotSimType>gazebo_ros_control/DefaultRobotHWSim</robotSimType>
      <legacyModeNS>true</legacyModeNS>
    </plugin>
  </gazebo>
  <gazebo reference="base_footprint">
    <material>Gazebo/Green</material>
  </gazebo>
  <gazebo reference="base_link">
    <material>Gazebo/Red</material>
  </gazebo>
  <gazebo reference="back_left_wheel_dir">
    <material>Gazebo/Green</material>
  </gazebo>
  <gazebo reference="back_right_wheel_dir">
    <material>Gazebo/Green</material>
  </gazebo>
  <gazebo reference="front_left_wheel_dir">
    <material>Gazebo/Green</material>
  </gazebo>
  <gazebo reference="front_left_wheel_dir">
    <material>Gazebo/Green</material>
  </gazebo>
  <!-- gazebo reference="back_left_wheel">
    <mu1 value="4.0"/>
    <mu2 value="1.0"/>
    <fdir1 value="1 0 0"/>
    <material>Gazebo/Grey</material>
  </gazebo -->
  <gazebo reference="back_left_wheel">
    <mu1 value="50.0"/>
    <mu2 value="50.0"/>
    <fdir1 value="1 0 0"/>
    <material>Gazebo/Grey</material>
  </gazebo>
  <gazebo reference="back_right_wheel">
    <mu1 value="50.0"/>
    <mu2 value="50.0"/>
    <fdir1 value="1 0 0"/>
    <material>Gazebo/Grey</material>
  </gazebo>
  <gazebo reference="front_left_wheel">
    <mu1 value="50.0"/>
    <mu2 value="50.0"/>
    <fdir1 value="1 0 0"/>
    <material>Gazebo/Grey</material>
  </gazebo>
  <gazebo reference="front_right_wheel">
    <mu1 value="50.0"/>
    <mu2 value="50.0"/>
    <fdir1 value="1 0 0"/>
    <material>Gazebo/Grey</material>
  </gazebo>
  <!-- camera -->
  <!-- gazebo reference="camera_link" -->
  <gazebo reference="camera_tilt_link">
    <mu1>0.2</mu1>
    <mu2>0.2</mu2>
    <material>Gazebo/Red</material>
    <sensor name="camera1" type="camera">
      <update_rate>30.0</update_rate>
      <camera name="head">
        <horizontal_fov>1.3962634</horizontal_fov>
        <image>
          <width>800</width>
          <height>800</height>
          <format>R8G8B8</format>
        </image>
        <clip>
          <near>0.02</near>
          <far>300</far>
        </clip>
        <noise>
          <type>gaussian</type>
          <!-- Noise is sampled independently per pixel on each frame.
               That pixel's noise value is added to each of its color
               channels, which at that point lie in the range [0,1]. -->
          <mean>0.0</mean>
          <stddev>0.007</stddev>
        </noise>
      </camera>
      <plugin filename="libgazebo_ros_camera.so" name="camera_controller">
        <alwaysOn>true</alwaysOn>
        <updateRate>0.0</updateRate>
        <cameraName>/summit/camera1</cameraName>
        <imageTopicName>image_raw</imageTopicName>
        <cameraInfoTopicName>camera_info</cameraInfoTopicName>
        <frameName>camera_tilt_link</frameName>
        <hackBaseline>0.07</hackBaseline>
        <distortionK1>0.0</distortionK1>
        <distortionK2>0.0</distortionK2>
        <distortionK3>0.0</distortionK3>
        <distortionT1>0.0</distortionT1>
        <distortionT2>0.0</distortionT2>
      </plugin>
    </sensor>
  </gazebo>
  <!-- hokuyo -->
  <gazebo reference="hokuyo_laser_link">
    <!-- sensor type="gpu_ray" name="head_hokuyo_sensor" -->
    <sensor name="head_hokuyo_sensor" type="ray">
      <pose>0 0 0 0 0 0</pose>
      <visualize>false</visualize>
      <update_rate>30</update_rate>
      <ray>
        <scan>
          <horizontal>
            <!-- samples>720</samples>
            <resolution>1</resolution>
            <min_angle>-1.570796</min_angle>
            <max_angle>1.570796</max_angle -->
            <samples>1081</samples>
            <resolution>1</resolution>
            <min_angle>2.35619449</min_angle>
            <!-- +/-135 deg -->
            <max_angle>-2.35619449</max_angle>
          </horizontal>
        </scan>
        <range>
          <min>0.10</min>
          <max>30.0</max>
          <resolution>0.01</resolution>
        </range>
        <noise>
          <type>gaussian</type>
          <mean>0.0</mean>
          <stddev>0.01</stddev>
        </noise>
      </ray>
      <!-- plugin name="gazebo_ros_head_hokuyo_controller" filename="libgazebo_ros_gpu_laser.so" -->
      <plugin filename="libgazebo_ros_laser.so" name="gazebo_ros_head_hokuyo_controller">
        <topicName>/scan</topicName>
        <frameName>hokuyo_laser_link</frameName>
      </plugin>
    </sensor>
  </gazebo>
  <gazebo>
    <plugin filename="libgazebo_ros_imu.so" name="ros_imu">
      <robotNamespace>/summit</robotNamespace>
      <topicName>imu_data</topicName>
      <bodyName>imu_link </bodyName>
      <serviceName>/imu_service</serviceName>
      <gaussianNoise>0.005</gaussianNoise>
    </plugin>
  </gazebo>
  <!-- BASE FOOTPRINT -->
  <!-- base_footprint is a fictitious link(frame) that is on the ground right below base_link origin,
             navigation stack depends on this frame -->
  <link name="base_footprint">
    <visual>
      <origin rpy="0 0 0" xyz="0 0 0"/>
      <geometry>
        <box size="0.001 0.001 0.001"/>
      </geometry>
    </visual>
    <collision>
      <origin rpy="0 0 0" xyz="0 0 0.0"/>
      <geometry>
        <box size="0.001 0.001 0.001"/>
      </geometry>
    </collision>
  </link>
  <joint name="base_footprint_joint" type="fixed">
    <!--NB: While you would think this would make it go up, it is oddly reversed.
      This moves the joint to 0,0,0 where we want it for rviz, etc. -->
    <!-- origin xyz="0 0 0.130" rpy="0 0 0" / -->
    <origin rpy="0 0 0" xyz="0 0 0.050"/>
    <parent link="base_footprint"/>
    <child link="base_link"/>
  </joint>
  <!-- BASE_LINK (RED) -->
  <link name="base_link">
    <inertial>
      <mass value="6.5"/>
      <origin xyz="0 0 0"/>
      <inertia ixx="0.21805" ixy="0.0" ixz="-0.001" iyy="0.33677" iyz="0.0" izz="0.20511"/>
    </inertial>
    <visual>
      <origin rpy="0 0 0" xyz="0 0 0"/>
      <geometry>
        <mesh filename="package://summit_description/meshes/summit_chassis.dae"/>
      </geometry>
    </visual>
    <collision>
      <origin rpy="0 0 0 " xyz="0 0 0.06"/>
      <geometry>
        <mesh filename="package://summit_description/meshes/summit_chassis.dae"/>
        <!-- box size = "0.56 0.4 0.2"/ -->
      </geometry>
    </collision>
  </link>
  <!-- DIRECTION BACK LEFT         -->
  <!-- =========================== -->
  <link name="back_left_wheel_dir">
    <inertial>
      <mass value="0.1"/>
      <!-- center of mass (com) is defined w.r.t. link local coord system -->
      <origin xyz="0 0 0"/>
      <inertia ixx="0.01" ixy="0.0" ixz="0.0" iyy="0.01" iyz="0.0" izz="0.01"/>
    </inertial>
    <visual>
      <!-- visual origin is defined w.r.t. link local coordinate system -->
      <origin rpy="0 0 0" xyz="0 0 0"/>
      <geometry>
        <cylinder length="0.025" radius="0.015"/>
        <!-- mesh filename="package://summit_description/meshes/wheel_axis.dae"/-->
      </geometry>
    </visual>
    <collision>
      <!-- collision origin is defined w.r.t. link local coord. system -->
      <origin rpy="0 0 0 " xyz="0 0 0"/>
      <geometry>
        <cylinder length="0.025" radius="0.015"/>
      </geometry>
    </collision>
  </link>
  <joint name="joint_back_left_wheel_dir" type="continuous">
    <parent link="base_link"/>
    <child link="back_left_wheel_dir"/>
    <origin rpy="0 0 0" xyz="-0.185 0.105 0"/>
    <axis rpy="0 0 0" xyz="0 0 1"/>
    <limit effort="100.0" lower="-0.7854" upper="0.7854" velocity="3.0"/>
    <joint_properties damping="0.2" friction="{steer_joint_friction}"/>
  </joint>
  <transmission name="joint_blw_trans_dir">
    <type>transmission_interface/SimpleTransmission</type>
    <joint name="joint_back_left_wheel_dir">
      <hardwareInterface>hardware_interface/EffortJointInterface</hardwareInterface>
    </joint>
    <actuator name="joint_blw_motor_dir">
      <hardwareInterface>EffortJointInterface</hardwareInterface>
      <mechanicalReduction>100.0</mechanicalReduction>
      <!-- motorTorqueConstant>1</motorTorqueConstant -->
    </actuator>
  </transmission>
  <!-- BACK LEFT WHEEL -->
  <link name="back_left_wheel">
    <inertial>
      <mass value="1.023"/>
      <origin xyz="0 0 0"/>
      <inertia ixx="0.0027" ixy="0.0" ixz="0.0" iyy="0.0039" iyz="0.0" izz="0.0027"/>
    </inertial>
    <visual>
      <origin rpy="0 0 0" xyz="0 0 0"/>
      <geometry>
        <mesh filename="package://summit_description/meshes/wheel.dae"/>
      </geometry>
      <material name="grey">
        <color rgba="0.5 0.5 0.5 1"/>
      </material>
    </visual>
    <collision>
      <origin rpy="0 0 0" xyz="0 0 0"/>
      <geometry>
        <mesh filename="package://summit_description/meshes/wheel.dae"/>
      </geometry>
    </collision>
  </link>
  <joint name="joint_back_left_wheel" type="continuous">
    <parent link="back_left_wheel_dir"/>
    <child link="back_left_wheel"/>
    <origin rpy="0 0 0" xyz="0.0 0.060 0"/>
    <axis rpy="0 0 0" xyz="0 1 0"/>
    <limit effort="100.0" velocity="200.0"/>
    <joint_properties damping="0.0" friction="{wheel_joint_friction}"/>
  </joint>
  <transmission name="joint_blw_trans">
    <type>transmission_interface/SimpleTransmission</type>
    <joint name="joint_back_left_wheel">
      <hardwareInterface>hardware_interface/VelocityJointInterface</hardwareInterface>
    </joint>
    <actuator name="joint_blw_motor">
      <hardwareInterface>VelocityJointInterface</hardwareInterface>
      <mechanicalReduction>1.0</mechanicalReduction>
      <!--motorTorqueConstant>1</motorTorqueConstant-->
    </actuator>
  </transmission>
  <!-- DIRECTION BACK RIGHT        -->
  <!-- =========================== -->
  <link name="back_right_wheel_dir">
    <inertial>
      <mass value="0.1"/>
      <!-- center of mass (com) is defined w.r.t. link local coord system -->
      <origin xyz="0 0 0"/>
      <inertia ixx="0.01" ixy="0.0" ixz="0.0" iyy="0.01" iyz="0.0" izz="0.01"/>
    </inertial>
    <visual>
      <!-- visual origin is defined w.r.t. link local coordinate system -->
      <origin rpy="0 0 0" xyz="0 0 0"/>
      <geometry>
        <cylinder length="0.025" radius="0.015"/>
      </geometry>
    </visual>
    <collision>
      <!-- collision origin is defined w.r.t. link local coord. system -->
      <origin rpy="0 0 0 " xyz="0 0 0"/>
      <geometry>
        <cylinder length="0.025" radius="0.015"/>
      </geometry>
    </collision>
  </link>
  <joint name="joint_back_right_wheel_dir" type="continuous">
    <parent link="base_link"/>
    <child link="back_right_wheel_dir"/>
    <origin rpy="0 0 0" xyz="-0.185 -0.105 0"/>
    <axis rpy="0 0 0" xyz="0 0 1"/>
    <limit effort="100.0" lower="-0.7854" upper="0.7854" velocity="3.0"/>
    <joint_properties damping="0.2" friction="{steer_joint_friction}"/>
  </joint>
  <transmission name="joint_brw_trans_dir">
    <type>transmission_interface/SimpleTransmission</type>
    <joint name="joint_back_right_wheel_dir">
      <hardwareInterface>hardware_interface/EffortJointInterface</hardwareInterface>
    </joint>
    <actuator name="joint_brw_motor_dir">
      <hardwareInterface>EffortJointInterface</hardwareInterface>
      <mechanicalReduction>100.0</mechanicalReduction>
      <!-- motorTorqueConstant>1</motorTorqueConstant -->
    </actuator>
  </transmission>
  <!-- BACK RIGHT WHEEL -->
  <link name="back_right_wheel">
    <inertial>
      <mass value="1.023"/>
      <origin xyz="0 0 0"/>
      <inertia ixx="0.0027" ixy="0.0" ixz="0.0" iyy="0.0039" iyz="0.0" izz="0.0027"/>
    </inertial>
    <visual>
      <origin rpy="0 0 0" xyz="0 0 0"/>
      <geometry>
        <mesh filename="package://summit_description/meshes/wheel.dae"/>
      </geometry>
      <material name="grey">
        <color rgba="0.5 0.5 0.5 1"/>
      </material>
    </visual>
    <collision>
      <origin rpy="0 0 0" xyz="0 0 0"/>
      <geometry>
        <mesh filename="package://summit_description/meshes/wheel.dae"/>
      </geometry>
    </collision>
  </link>
  <joint name="joint_back_right_wheel" type="continuous">
    <parent link="back_right_wheel_dir"/>
    <child link="back_right_wheel"/>
    <origin rpy="0 0 0" xyz="0.0 -0.060 0"/>
    <axis rpy="0 0 0" xyz="0 1 0"/>
    <limit effort="100.0" velocity="200.0"/>
    <joint_properties damping="0.0" friction="{wheel_joint_friction}"/>
  </joint>
  <transmission name="joint_brw_trans">
    <type>transmission_interface/SimpleTransmission</type>
    <joint name="joint_back_right_wheel">
      <hardwareInterface>hardware_interface/VelocityJointInterface</hardwareInterface>
    </joint>
    <actuator name="joint_brw_motor">
      <hardwareInterface>VelocityJointInterface</hardwareInterface>
      <mechanicalReduction>1.0</mechanicalReduction>
      <!-- motorTorqueConstant>1</motorTorqueConstant -->
    </actuator>
  </transmission>
  <!-- DIRECTION FORWARD LEFT      -->
  <!-- =========================== -->
  <link name="front_left_wheel_dir">
    <inertial>
      <mass value="0.1"/>
      <!-- center of mass (com) is defined w.r.t. link local coord system -->
      <origin xyz="0 0 0"/>
      <inertia ixx="0.01" ixy="0.0" ixz="0.0" iyy="0.01" iyz="0.0" izz="0.01"/>
    </inertial>
    <visual>
      <!-- visual origin is defined w.r.t. link local coordinate system -->
      <origin rpy="0 0 0" xyz="0 0 0"/>
      <geometry>
        <cylinder length="0.025" radius="0.015"/>
      </geometry>
    </visual>
    <collision>
      <!-- collision origin is defined w.r.t. link local coord. system -->
      <origin rpy="0 0 0 " xyz="0 0 0"/>
      <geometry>
        <cylinder length="0.025" radius="0.015"/>
      </geometry>
    </collision>
  </link>
  <joint name="joint_front_left_wheel_dir" type="continuous">
    <parent link="base_link"/>
    <child link="front_left_wheel_dir"/>
    <origin rpy="0 0 0" xyz="0.185 0.105 0"/>
    <axis rpy="0 0 0" xyz="0 0 1"/>
    <limit effort="100.0" lower="-0.7854" upper="0.7854" velocity="3.0"/>
    <joint_properties damping="0.2" friction="{steer_joint_friction}"/>
  </joint>
  <transmission name="joint_flw_trans_dir">
    <type>transmission_interface/SimpleTransmission</type>
    <joint name="joint_front_left_wheel_dir">
      <hardwareInterface>hardware_interface/EffortJointInterface</hardwareInterface>
    </joint>
    <actuator name="joint_flw_motor_dir">
      <hardwareInterface>EffortJointInterface</hardwareInterface>
      <mechanicalReduction>100.0</mechanicalReduction>
      <!-- motorTorqueConstant>1</motorTorqueConstant -->
    </actuator>
  </transmission>
  <!-- FRONT LEFT WHEEL (GREY) -->
  <link name="front_left_wheel">
    <inertial>
      <mass value="1.023"/>
      <origin xyz="0 0 0"/>
      <inertia ixx="0.0027" ixy="0.0" ixz="0.0" iyy="0.0039" iyz="0.0" izz="0.0027"/>
    </inertial>
    <visual>
      <origin rpy="0 0 0" xyz="0 0 0"/>
      <geometry>
        <mesh filename="package://summit_description/meshes/wheel.dae"/>
      </geometry>
      <material name="gray">
        <color rgba="0.5 0.5 0.5 1"/>
      </material>
    </visual>
    <collision>
      <origin rpy="0 0 0" xyz="0 0 0"/>
      <geometry>
        <mesh filename="package://summit_description/meshes/wheel.dae"/>
      </geometry>
    </collision>
  </link>
  <joint name="joint_front_left_wheel" type="continuous">
    <parent link="front_left_wheel_dir"/>
    <child link="front_left_wheel"/>
    <origin rpy="0 0 0" xyz="0.0 0.060 0"/>
    <axis rpy="0 0 0" xyz="0 1 0"/>
    <limit effort="100.0" velocity="200.0"/>
    <joint_properties damping="0.0" friction="{wheel_joint_friction}"/>
  </joint>
  <transmission name="joint_flw_trans">
    <type>transmission_interface/SimpleTransmission</type>
    <joint name="joint_front_left_wheel">
      <hardwareInterface>hardware_interface/VelocityJointInterface</hardwareInterface>
    </joint>
    <actuator name="joint_flw_motor">
      <hardwareInterface>VelocityJointInterface</hardwareInterface>
      <mechanicalReduction>1.0</mechanicalReduction>
      <!-- motorTorqueConstant>1</motorTorqueConstant -->
    </actuator>
  </transmission>
  <!-- DIRECTION FORWARD RIGHT     -->
  <!-- =========================== -->
  <link name="front_right_wheel_dir">
    <inertial>
      <mass value="0.1"/>
      <!-- center of mass (com) is defined w.r.t. link local coord system -->
      <origin xyz="0 0 0"/>
      <inertia ixx="0.01" ixy="0.0" ixz="0.0" iyy="0.01" iyz="0.0" izz="0.01"/>
    </inertial>
    <visual>
      <!-- visual origin is defined w.r.t. link local coordinate system -->
      <origin rpy="0 0 0" xyz="0 0 0"/>
      <geometry>
        <cylinder length="0.025" radius="0.015"/>
      </geometry>
    </visual>
    <collision>
      <!-- collision origin is defined w.r.t. link local coord. system -->
      <origin rpy="0 0 0 " xyz="0 0 0"/>
      <geometry>
        <cylinder length="0.025" radius="0.015"/>
      </geometry>
    </collision>
  </link>
  <joint name="joint_front_right_wheel_dir" type="continuous">
    <parent link="base_link"/>
    <child link="front_right_wheel_dir"/>
    <origin rpy="0 0 0" xyz="0.185 -0.105 0"/>
    <axis rpy="0 0 0" xyz="0 0 1"/>
    <limit effort="100.0" lower="-0.7854" upper="0.7854" velocity="3.0"/>
    <joint_properties damping="0.2" friction="{steer_joint_friction}"/>
  </joint>
  <transmission name="joint_frw_trans_dir">
    <type>transmission_interface/SimpleTransmission</type>
    <joint name="joint_front_right_wheel_dir">
      <hardwareInterface>hardware_interface/EffortJointInterface</hardwareInterface>
    </joint>
    <actuator name="joint_frw_motor_dir">
      <hardwareInterface>EffortJointInterface</hardwareInterface>
      <mechanicalReduction>100.0</mechanicalReduction>
      <!-- motorTorqueConstant>1</motorTorqueConstant -->
    </actuator>
  </transmission>
  <!-- FRONT RIGHT WHEEL (GREY) -->
  <link name="front_right_wheel">
    <inertial>
      <mass value="1.023"/>
      <origin xyz="0 0 0"/>
      <inertia ixx="0.0027" ixy="0.0" ixz="0.0" iyy="0.0039" iyz="0.0" izz="0.0027"/>
    </inertial>
    <visual>
      <origin rpy="0 0 0" xyz="0 0 0"/>
      <geometry>
        <mesh filename="package://summit_description/meshes/wheel.dae"/>
      </geometry>
      <material name="grey">
        <color rgba="0.5 0.5 0.5 1"/>
      </material>
    </visual>
    <collision>
      <origin rpy="0 0 0" xyz="0 0 0"/>
      <geometry>
        <mesh filename="package://summit_description/meshes/wheel.dae"/>
      </geometry>
    </collision>
  </link>
  <joint name="joint_front_right_wheel" type="continuous">
    <parent link="front_right_wheel_dir"/>
    <child link="front_right_wheel"/>
    <origin rpy="0 0 0" xyz="0.0 -0.060 0"/>
    <axis rpy="0 0 0" xyz="0 1 0"/>
    <limit effort="100.0" velocity="200.0"/>
    <joint_properties damping="0.0" friction="{wheel_joint_friction}"/>
  </joint>
  <transmission name="joint_frw_trans">
    <type>transmission_interface/SimpleTransmission</type>
    <joint name="joint_front_right_wheel">
      <hardwareInterface>hardware_interface/VelocityJointInterface</hardwareInterface>
    </joint>
    <actuator name="joint_frw_motor">
      <hardwareInterface>VelocityJointInterface</hardwareInterface>
      <mechanicalReduction>1.0</mechanicalReduction>
      <!-- motorTorqueConstant>1</motorTorqueConstant -->
    </actuator>
  </transmission>
  <!-- HOKUYO SENSOR -->
  <joint name="hokuyo_laser_joint" type="fixed">
    <axis xyz="0 1 0"/>
    <origin xyz="0.226 0 0.120"/>
    <parent link="base_link"/>
    <child link="hokuyo_laser_link"/>
  </joint>
  <link name="hokuyo_laser_link" type="laser">
    <collision>
      <origin rpy="0 0 0" xyz="0 0 0"/>
      <geometry>
        <box size="0.1 0.1 0.1"/>
      </geometry>
    </collision>
    <visual>
      <origin rpy="0 0 0" xyz="0 0 0"/>
      <geometry>
        <mesh filename="package://summit_description/meshes/hokuyo-utm30-lx.dae"/>
      </geometry>
    </visual>
    <inertial>
      <mass value="1e-5"/>
      <origin rpy="0 0 0" xyz="0 0 0"/>
      <inertia ixx="1e-6" ixy="0" ixz="0" iyy="1e-6" iyz="0" izz="1e-6"/>
    </inertial>
  </link>
  <!-- IMU SENSOR -->
  <joint name="imu_joint" type="fixed">
    <axis xyz="1 0 0"/>
    <!-- 0 1 0 -->
    <origin xyz="0 0 0.2825"/>
    <parent link="base_link"/>
    <child link="imu_link"/>
  </joint>
  <link name="imu_link">
    <inertial>
      <mass value="0.001"/>
      <origin rpy="0 0 0" xyz="0 0 0"/>
      <inertia ixx="0.0001" ixy="0" ixz="0" iyy="0.000001" iyz="0" izz="0.0001"/>
    </inertial>
    <visual>
      <origin rpy="0 0 0" xyz="0 0 0"/>
      <geometry>
        <box size="0.001 0.001 0.001"/>
      </geometry>
    </visual>
    <collision>
      <origin rpy="0 0 0" xyz="0 0 0"/>
      <geometry>
        <box size=".001 .001 .001"/>
      </geometry>
    </collision>
  </link>
  <!-- AXIS PTZ CAMERA WITH PAN AND TILT -->
  <link name="camera_base_link">
    <inertial>
      <mass value="0.1"/>
      <origin rpy="0 0 0" xyz="0 0 0"/>
      <inertia ixx="0.1" ixy="0" ixz="0" iyy="0.1" iyz="0" izz="0.1"/>
    </inertial>
  </link>
  <joint name="joint_camera" type="fixed">
    <axis xyz="0 1 0"/>
    <!--origin xyz="0.180 0.0 0.270"/-->
    <origin xyz="0.150 0.0 0.240"/>
    <parent link="base_link"/>
    <child link="camera_base_link"/>
  </joint>
  <link name="camera_pan_link">
    <inertial>
      <mass value="0.1"/>
      <origin rpy="0 0 0" xyz="0 0 0"/>
      <inertia ixx="0.1" ixy="0" ixz="0" iyy="0.1" iyz="0" izz="0.1"/>
    </inertial>
  </link>
  <joint name="joint_camera_pan" type="continuous">
    <axis xyz="0 0 1"/>
    <origin xyz="0.0 0.0 0.0"/>
    <parent link="camera_base_link"/>
    <child link="camera_pan_link"/>
    <limit effort="100.0" lower="-3.1416" upper="3.1416" velocity="100.0"/>
    <joint_properties damping="0.1" friction="{ptz_joint_friction}"/>
  </joint>
  <transmission name="joint_pan_trans">
    <type>transmission_interface/SimpleTransmission</type>
    <joint name="joint_camera_pan">
      <hardwareInterface>hardware_interface/EffortJointInterface</hardwareInterface>
    </joint>
    <actuator name="pan_motor">
      <hardwareInterface>EffortJointInterface</hardwareInterface>
      <mechanicalReduction>1.0</mechanicalReduction>
    </actuator>
  </transmission>
  <link name="camera_tilt_link">
    <inertial>
      <mass value="0.1"/>
      <!-- origin xyz="0 0 0" rpy="0 0 0" / -->
      <origin rpy="0 0 0" xyz="0 0 0.3"/>
      <inertia ixx="0.1" ixy="0" ixz="0" iyy="0.1" iyz="0" izz="0.1"/>
    </inertial>
  </link>
  <joint name="joint_camera_tilt" type="continuous">
    <axis xyz="0 1 0"/>
    <origin xyz="0.0 0.0 0.0"/>
    <parent link="camera_pan_link"/>
    <child link="camera_tilt_link"/>
    <limit effort="100.0" lower="-1.5708" upper="1.5708" velocity="100.0"/>
    <joint_properties damping="0.1" friction="{ptz_joint_friction}"/>
  </joint>
  <transmission name="joint_tilt_trans">
    <type>transmission_interface/SimpleTransmission</type>
    <joint name="joint_camera_tilt">
      <hardwareInterface>hardware_interface/EffortJointInterface</hardwareInterface>
    </joint>
    <actuator name="tilt_motor">
      <hardwareInterface>EffortJointInterface</hardwareInterface>
      <mechanicalReduction>1.0</mechanicalReduction>
    </actuator>
  </transmission>
</robot>

